Workbook

Sheet Consolidado_Chincha
A1: N° | B1: APELLIDOS | C1: NOMBRES | D1: DNI | E1: CODIGO | F1: TELEFONO | G1: CORREO | H1: AREA | I1: CARRERA | J1: SEDE DE ESTUDIO | K1: ASISTENCIA | L1: COMUNICACIÓN (25 Ptos) | M1: % | N1: H. COMUNICATIVAS (10 Pts) | O1: % | P1: MATEMATICA (50 Pts) | Q1: % | R1: CTA (15 Pts) | S1: % | T1: TOTAL (100 Pts) | U1: % | V1: CONDICIÓN | W1: MODALIDAD | X1: FECHA | Y1: EXAMEN | Z1: MODALIDAD DE INGRESO
A2: 1 | B2: YARLEQUE CABELLO | C2: MARIBEL ROXANA | D2: 48037096 | E2: A261001149 | G2: ladesiempre050@gmail.com | H2: B | I2: ENFERMERÍA | J2: Filial-Huacho | K2: ASISTIÓ | L2: 14 | M2: 0.56 | N2: 4 | O2: 0.4 | P2: 10 | Q2: 0.33333333 | R2: 14 | S2: 0.4 | T2: 42 | U2: 0.42 | V2: INGRESÓ | W2: VIRTUAL | X2: 46011 | Y2: DICIEMBRE | Z2: EXAMEN ORDINARIO
A3: 2 | B3: HUACHO QUITO | C3: LEISLE ZOFIA | D3: 60248123 | E3: A261001214 | G3: leslyhuacho462@gmail.com | H3: B | I3: ENFERMERÍA | J3: Filial-Huacho | K3: ASISTIÓ | L3: 15 | M3: 0.6 | N3: 5 | O3: 0.5 | P3: 8 | Q3: 0.26666667 | R3: 15 | S3: 0.42857143 | T3: 43 | U3: 0.43 | V3: INGRESÓ | W3: VIRTUAL | X3: 46011 | Y3: DICIEMBRE | Z3: EXAMEN ORDINARIO
A4: 3 | B4: GIRALDO JUSTINO | C4: BRITHANNY HARLEY | D4: 60459269 | E4: A261001236 | G4: harleyjustino2006@gmail.com | H4: B | I4: ENFERMERÍA | J4: Filial-Huacho | K4: ASISTIÓ | L4: 20 | M4: 0.8 | N4: 7 | O4: 0.7 | P4: 23 | Q4: 0.76666667 | R4: 33 | S4: 0.94285714 | T4: 83 | U4: 0.83 | V4: INGRESÓ | W4: VIRTUAL | X4: 46011 | Y4: DICIEMBRE | Z4: EXAMEN ORDINARIO
A5: 4 | B5: ACEVEDO GUEVARA | C5: YHADIRA MICHELLE | D5: 60577442 | E5: A261000900 | F5: 996186698 | G5: isabelhuertas507@gmail.com | H5: B | I5: ENFERMERÍA | J5: Filial-Huacho | K5: ASISTIÓ | L5: 10 | M5: 0.4 | N5: 6 | O5: 0.6 | P5: 17 | Q5: 0.56666667 | R5: 27 | S5: 0.77142857 | T5: 60 | U5: 0.6 | V5: INGRESÓ | W5: VIRTUAL | X5: 46011 | Y5: DICIEMBRE | Z5: EXAMEN ORDINARIO
A6: 5 | B6: CHAVEZ SALVADOR | C6: ROSALINDA NATALIA | D6: 60650008 | E6: A261001205 | G6: rosalindachavezsalvador7@gmail.com | H6: B | I6: ENFERMERÍA | J6: Filial-Huacho | K6: ASISTIÓ | L6: 17 | M6: 0.68 | N6: 8 | O6: 0.8 | P6: 27 | Q6: 0.9 | R6: 32 | S6: 0.91428571 | T6: 84 | U6: 0.84 | V6: INGRESÓ | W6: VIRTUAL | X6: 46011 | Y6: DICIEMBRE | Z6: PRIMERA OPCIÓN
A7: 6 | B7: FLORES MEZA | C7: JACKELINE FIORELLA | D7: 61035075 | E7: A261001113 | G7: fiorelaflores701@gmail.com | H7: B | I7: ENFERMERÍA | J7: Filial-Huacho | K7: ASISTIÓ | L7: 11 | M7: 0.44 | N7: 5 | O7: 0.5 | P7: 20 | Q7: 0.66666667 | R7: 25 | S7: 0.71428571 | T7: 61 | U7: 0.61 | V7: INGRESÓ | W7: VIRTUAL | X7: 46011 | Y7: DICIEMBRE | Z7: EXAMEN ORDINARIO
A8: 7 | B8: ORTIZ PASCUAL | C8: ARIANA EDELINA | D8: 61062460 | E8: A261001233 | G8: arianaortizpascual@gmail.com | H8: B | I8: ENFERMERÍA | J8: Filial-Huacho | K8: ASISTIÓ | L8: 17 | M8: 0.68 | N8: 7 | O8: 0.7 | P8: 15 | Q8: 0.5 | R8: 23 | S8: 0.65714286 | T8: 62 | U8: 0.62 | V8: INGRESÓ | W8: VIRTUAL | X8: 46011 | Y8: DICIEMBRE | Z8: EXAMEN ORDINARIO
A9: 8 | B9: ZAVALETA CASTILLO | C9: STHEFANI YASHURI | D9: 61113531 | E9: A261000898 | G9: sthefanyzavaleta74@gmail.com | H9: B | I9: ENFERMERÍA | J9: Filial-Huacho | K9: ASISTIÓ | L9: 13 | M9: 0.52 | N9: 5 | O9: 0.5 | P9: 11 | Q9: 0.36666667 | R9: 24 | S9: 0.68571429 | T9: 53 | U9: 0.53 | V9: INGRESÓ | W9: VIRTUAL | X9: 46011 | Y9: DICIEMBRE | Z9: EXAMEN ORDINARIO
A10: 9 | B10: ROMERO AIRA | C10: JUAN DAVID | D10: 61369069 | E10: A261001217 | G10: shetosbv16@gmail.com | H10: B | I10: ENFERMERÍA | J10: Filial-Huacho | K10: ASISTIÓ | L10: 17 | M10: 0.68 | N10: 8 | O10: 0.8 | P10: 25 | Q10: 0.83333333 | R10: 30 | S10: 0.85714286 | T10: 80 | U10: 0.8 | V10: INGRESÓ | W10: VIRTUAL | X10: 46011 | Y10: DICIEMBRE | Z10: PRIMERA OPCIÓN
A11: 10 | B11: SANDOVAL FLORES | C11: JULIETA DEL CARMEN | D11: 61505762 | E11: A261001027 | G11: irmafloresbartolome@gmail.com | H11: B | I11: ENFERMERÍA | J11: Filial-Huacho | K11: ASISTIÓ | L11: 16 | M11: 0.64 | N11: 7 | O11: 0.7 | P11: 17 | Q11: 0.56666667 | R11: 29 | S11: 0.82857143 | T11: 69 | U11: 0.69 | V11: INGRESÓ | W11: VIRTUAL | X11: 46011 | Y11: DICIEMBRE | Z11: PRIMERA OPCIÓN
A12: 11 | B12: ROBLES CARQUIN | C12: GRACE ABIGAIL BRESHITH | D12: 61506255 | E12: A261001280 | G12: graceroblescarquin0110@gmail.com | H12: B | I12: ENFERMERÍA | J12: Filial-Huacho | K12: ASISTIÓ | L12: 5 | M12: 0.2 | N12: 4 | O12: 0.4 | P12: 13 | Q12: 0.43333333 | R12: 28 | S12: 0.8 | T12: 50 | U12: 0.5 | V12: INGRESÓ | W12: VIRTUAL | X12: 46011 | Y12: DICIEMBRE | Z12: PRIMERA OPCIÓN
A13: 12 | B13: CHUMBES ZENOZAIN | C13: CARLOS SEBASTIAN | D13: 71894777 | E13: A261000964 | G13: sebastianzenozain038@gmail.com | H13: B | I13: ENFERMERÍA | J13: Filial-Huacho | K13: ASISTIÓ | L13: 14 | M13: 0.56 | N13: 8 | O13: 0.8 | P13: 16 | Q13: 0.53333333 | R13: 26 | S13: 0.74285714 | T13: 64 | U13: 0.64 | V13: INGRESÓ | W13: VIRTUAL | X13: 46011 | Y13: DICIEMBRE | Z13: EXAMEN ORDINARIO
A14: 13 | B14: TOLENTINO SERPA | C14: ANGIE NYCOLE | D14: 75978308 | E14: A261000963 | G14: serpaangie@gmail.com | H14: B | I14: ENFERMERÍA | J14: Filial-Huacho | K14: ASISTIÓ | L14: 17 | M14: 0.68 | N14: 8 | O14: 0.8 | P14: 26 | Q14: 0.86666667 | R14: 35 | S14: 1 | T14: 86 | U14: 0.86 | V14: INGRESÓ | W14: VIRTUAL | X14: 46011 | Y14: DICIEMBRE | Z14: EXAMEN ORDINARIO
A15: 14 | B15: ORTIZ RAMOS | C15: SAMIRA VIVIANA | D15: 76345536 | E15: A261000943 | G15: samiraortizramos25@gmail.com | H15: B | I15: ENFERMERÍA | J15: Filial-Huacho | K15: ASISTIÓ | L15: 20 | M15: 0.8 | N15: 8 | O15: 0.8 | P15: 11 | Q15: 0.36666667 | R15: 32 | S15: 0.91428571 | T15: 71 | U15: 0.71 | V15: INGRESÓ | W15: VIRTUAL | X15: 46011 | Y15: DICIEMBRE | Z15: EXAMEN ORDINARIO
A16: 15 | B16: PALMA HUANCA | C16: DIANA CAROLINA | D16: 46430439 | E16: A261000851 | G16: dianaisis1990@gmail.com | H16: B | I16: OBSTETRICIA | J16: Filial-Huacho | K16: ASISTIÓ | L16: 12 | M16: 0.48 | N16: 3 | O16: 0.3 | P16: 20 | Q16: 0.66666667 | R16: 23 | S16: 0.65714286 | T16: 58 | U16: 0.58 | V16: INGRESÓ | W16: VIRTUAL | X16: 46011 | Y16: DICIEMBRE | Z16: EXAMEN ORDINARIO
A17: 16 | B17: FERRER QUISPE | C17: HALISON NICOLE | D17: 60565694 | E17: A261001223 | G17: alissonferrerquispe@gmail.com | H17: B | I17: OBSTETRICIA | J17: Filial-Huacho | K17: ASISTIÓ | L17: 11 | M17: 0.44 | N17: 4 | O17: 0.4 | P17: 18 | Q17: 0.6 | R17: 21 | S17: 0.6 | T17: 54 | U17: 0.54 | V17: INGRESÓ | W17: VIRTUAL | X17: 46011 | Y17: DICIEMBRE | Z17: EXAMEN ORDINARIO
... A23: 22 | B23: ROMAN UNZUETA | C23: MASSIEL ANDREA | D23: 61565276 | E23: A261000986 | G23: andrearomanunzueta036@gmail.com | H23: B | I23: OBSTETRICIA | J23: Filial-Huacho | K23: ASISTIÓ | L23: 17 | M23: 0.68 | N23: 7 | O23: 0.7 | P23: 26 | Q23: 0.86666667 | R23: 29 | S23: 0.82857143 | T23: 79 | U23: 0.79 | V23: INGRESÓ | W23: VIRTUAL | X23: 46011 | Y23: DICIEMBRE | Z23: PRIMERA OPCIÓN
A24: 23 | B24: LEON CHINCHAY | C24: GERAME DENNIS | D24: 75108509 | E24: A261000871 | F24: 905612939 | G24: leongerami10@gmail.com | H24: B | I24: OBSTETRICIA | J24: Filial-Huacho | K24: ASISTIÓ | L24: 16 | M24: 0.64 | N24: 5 | O24: 0.5 | P24: 24 | Q24: 0.8 | R24: 31 | S24: 0.88571429 | T24: 76 | U24: 0.76 | V24: INGRESÓ | W24: VIRTUAL | X24: 46011 | Y24: DICIEMBRE | Z24: EXAMEN ORDINARIO
A25: 24 | B25: ROMERO LLAGAS | C25: NICOLE NASAY | D25: 75975765 | E25: A261000897 | G25: nasayromerollagas@gmail.com | H25: B | I25: OBSTETRICIA | J25: Filial-Huacho | K25: ASISTIÓ | L25: 11 | M25: 0.44 | N25: 7 | O25: 0.7 | P25: 10 | Q25: 0.33333333 | R25: 30 | S25: 0.85714286 | T25: 58 | U25: 0.58 | V25: INGRESÓ | W25: VIRTUAL | X25: 46011 | Y25: DICIEMBRE | Z25: EXAMEN ORDINARIO
A26: 25 | B26: AURIS ANDRES | C26: NAYDU EVELYN | D26: 47351249 | E26: A261000955 | G26: nayduaurisandres20@gmail.com | H26: B | I26: PSICOLOGÍA | J26: Filial-Huacho | K26: ASISTIÓ | L26: 19 | M26: 0.76 | N26: 9 | O26: 0.9 | P26: 13 | Q26: 0.43333333 | R26: 15 | S26: 0.42857143 | T26: 56 | U26: 0.56 | V26: INGRESÓ | W26: VIRTUAL | X26: 46011 | Y26: DICIEMBRE | Z26: EXAMEN ORDINARIO
A27: 26 | B27: RAMIREZ LLIQUE | C27: SANDRA CORINA | D27: 48111510 | E27: A261001259 | G27: sandracorina30@gmail.com | H27: B | I27: PSICOLOGÍA | J27: Filial-Huacho | K27: ASISTIÓ | L27: 13 | M27: 0.52 | N27: 6 | O27: 0.6 | P27: 13 | Q27: 0.43333333 | R27: 28 | S27: 0.8 | T27: 60 | U27: 0.6 | V27: INGRESÓ | W27: VIRTUAL | X27: 46011 | Y27: DICIEMBRE | Z27: EXAMEN ORDINARIO
A28: 27 | B28: MELGAR MEDINA | C28: LUCIANA LISET | D28: 60195925 | E28: A261001277 | G28: lucymelgmed@gmail.com | H28: B | I28: PSICOLOGÍA | J28: Filial-Huacho | K28: ASISTIÓ | L28: 8 | M28: 0.32 | N28: 8 | O28: 0.8 | P28: 23 | Q28: 0.76666667 | R28: 13 | S28: 0.37142857 | T28: 52 | U28: 0.52 | V28: INGRESÓ | W28: VIRTUAL | X28: 46011 | Y28: DICIEMBRE | Z28: EXAMEN ORDINARIO
A29: 28 | B29: SIGUEÑAS BEDON | C29: HELEN YASHURIN | D29: 60405475 | E29: A261001005 | G29: helenyashurinsiguenasbedon@gmail.com | H29: B | I29: PSICOLOGÍA | J29: Filial-Huacho | K29: ASISTIÓ | L29: 17 | M29: 0.68 | N29: 8 | O29: 0.8 | P29: 23 | Q29: 0.76666667 | R29: 29 | S29: 0.82857143 | T29: 77 | U29: 0.77 | V29: INGRESÓ | W29: VIRTUAL | X29: 46011 | Y29: DICIEMBRE | Z29: PRIMERA OPCIÓN
A30: 29 | B30: FELIX MENDOZA | C30: DULCE INES | D30: 60584671 | E30: A261001161 | G30: inesmid15@gmail.com | H30: B | I30: PSICOLOGÍA | J30: Filial-Huacho | K30: ASISTIÓ | L30: 12 | M30: 0.48 | N30: 8 | O30: 0.8 | P30: 23 | Q30: 0.76666667 | R30: 23 | S30: 0.65714286 | T30: 66 | U30: 0.66 | V30: INGRESÓ | W30: VIRTUAL | X30: 46011 | Y30: DICIEMBRE | Z30: EXAMEN ORDINARIO
A31: 30 | B31: BECERRA QUIÑONEZ | C31: EVER DAVID | D31: 60620325 | E31: A261000935 | G31: everdavidbecerra@gmail.com | H31: B | I31: PSICOLOGÍA | J31: Filial-Huacho | K31: ASISTIÓ | L31: 16 | M31: 0.64 | N31: 8 | O31: 0.8 | P31: 6 | Q31: 0.2 | R31: 12 | S31: 0.34285714 | T31: 42 | U31: 0.42 | V31: INGRESÓ | W31: VIRTUAL | X31: 46011 | Y31: DICIEMBRE | Z31: PRIMERA OPCIÓN
A32: 31 | B32: TASAYCO ROJAS | C32: AIKO VICTORIA | D32: 60620334 | E32: A261001070 | G32: victoriatasayco.14@gmail.com | H32: B | I32: PSICOLOGÍA | J32: Filial-Huacho | K32: ASISTIÓ | L32: 19 | M32: 0.76 | N32: 8 | O32: 0.8 | P32: 20 | Q32: 0.66666667 | R32: 29 | S32: 0.82857143 | T32: 76 | U32: 0.76 | V32: INGRESÓ | W32: VIRTUAL | X32: 46011 | Y32: DICIEMBRE | Z32: PRIMERA OPCIÓN
A33: 32 | B33: BISSO DE LOS SANTOS | C33: AIXA ESTEFANIA | D33: 60650142 | E33: A261001010 | G33: aixab036@gmail.com | H33: B | I33: PSICOLOGÍA | J33: Filial-Huacho | K33: ASISTIÓ | L33: 19 | M33: 0.76 | N33: 9 | O33: 0.9 | P33: 29 | Q33: 0.96666667 | R33: 29 | S33: 0.82857143 | T33: 86 | U33: 0.86 | V33: INGRESÓ | W33: VIRTUAL | X33: 46011 | Y33: DICIEMBRE | Z33: PRIMERA OPCIÓN
A34: 33 | B34: RAMOS LLAGAS | C34: STEFANIE GERALDINE | D34: 60803824 | E34: A261000146 | G34: geraldineyoriana@gmail.com | H34: B | I34: PSICOLOGÍA | J34: FILIAL HUAURA | K34: ASISTIÓ | L34: 17 | M34: 0.68 | N34: 7 | O34: 0.7 | P34: 18 | Q34: 0.6 | R34: 31 | S34: 0.88571429 | T34: 73 | U34: 0.73 | V34: INGRESÓ | W34: VIRTUAL | X34: 46011 | Y34: DICIEMBRE | Z34: EXAMEN ORDINARIO
A35: 34 | B35: CUBAS AREVALO | C35: ERIKA ANGELIQUE | D35: 61062624 | E35: A261000931 | G35: erika2018cubas@gmail.com | H35: B | I35: PSICOLOGÍA | J35: Filial-Huacho | K35: ASISTIÓ | L35: 17 | M35: 0.68 | N35: 6 | O35: 0.6 | P35: 22 | Q35: 0.73333333 | R35: 31 | S35: 0.88571429 | T35: 76 | U35: 0.76 | V35: INGRESÓ | W35: VIRTUAL | X35: 46011 | Y35: DICIEMBRE | Z35: EXAMEN ORDINARIO
A36: 35 | B36: FLORES CASTILLO | C36: NAYELEE YERAY | D36: 61454735 | E36: A261000995 | G36: nayeleefflores14@gmail.com | H36: B | I36: PSICOLOGÍA | J36: Filial-Huacho | K36: ASISTIÓ | L36: 20 | M36: 0.8 | N36: 9 | O36: 0.9 | P36: 28 | Q36: 0.93333333 | R36: 28 | S36: 0.8 | T36: 85 | U36: 0.85 | V36: INGRESÓ | W36: VIRTUAL | X36: 46011 | Y36: DICIEMBRE | Z36: PRIMERA OPCIÓN
A37: 36 | B37: ALCANTARA HUERTA | C37: CARLOS HAILTON | D37: 61760402 | E37: A261001155 | G37: carloshalcantara18@gmail.com | H37: B | I37: PSICOLOGÍA | J37: SEDE CHINCHA ALTA | K37: ASISTIÓ | L37: 22 | M37: 0.88 | N37: 9 | O37: 0.9 | P37: 21 | Q37: 0.7 | R37: 28 | S37: 0.8 | T37: 80 | U37: 0.8 | V37: INGRESÓ | W37: VIRTUAL | X37: 46011 | Y37: DICIEMBRE | Z37: PRIMERA OPCIÓN
A38: 37 | B38: MANRIQUE ARANDA | C38: JOSHUA GABRIEL ANTONIO | D38: 61760417 | E38: A261000987 | F38: 935020096 | G38: joshua_211217@hotmail.com | H38: B | I38: PSICOLOGÍA | J38: Filial-Huacho | K38: ASISTIÓ | L38: 21 | M38: 0.84 | N38: 9 | O38: 0.9 | P38: 26 | Q38: 0.86666667 | R38: 33 | S38: 0.94285714 | T38: 89 | U38: 0.89 | V38: INGRESÓ | W38: VIRTUAL | X38: 46011 | Y38: DICIEMBRE | Z38: PRIMERA OPCIÓN
A39: 38 | B39: PALA VEGA | C39: ROSA ELENA | D39: 71396975 | E39: A261001103 | G39: palavegarosa@gmail.com | H39: B | I39: PSICOLOGÍA | J39: Filial-Huacho | K39: ASISTIÓ | L39: 19 | M39: 0.76 | N39: 7 | O39: 0.7 | P39: 17 | Q39: 0.56666667 | R39: 29 | S39: 0.82857143 | T39: 72 | U39: 0.72 | V39: INGRESÓ | W39: VIRTUAL | X39: 46011 | Y39: DICIEMBRE | Z39: EXAMEN ORDINARIO
A40: 39 | B40: TRUJILLO FELIX | C40: ADELAIDA ANGELA | D40: 71654895 | E40: A261000999 | G40: angelatrujillofelix881@gmail.com | H40: B | I40: PSICOLOGÍA | J40: Filial-Huacho | K40: ASISTIÓ | L40: 17 | M40: 0.68 | N40: 9 | O40: 0.9 | P40: 25 | Q40: 0.83333333 | R40: 31 | S40: 0.88571429 | T40: 82 | U40: 0.82 | V40: INGRESÓ | W40: VIRTUAL | X40: 46011 | Y40: DICIEMBRE | Z40: EXAMEN ORDINARIO
A41: 40 | B41: HERNANDEZ RODRIGUEZ | C41: FIORELLA VALENTINA | D41: 72068824 | E41: A261001196 | G41: hernandezfiorellaelena83@gmail.com | H41: B | I41: PSICOLOGÍA | J41: Filial-Huacho | K41: ASISTIÓ | L41: 14 | M41: 0.56 | N41: 7 | O41: 0.7 | P41: 8 | Q41: 0.26666667 | R41: 12 | S41: 0.34285714 | T41: 41 | U41: 0.41 | V41: INGRESÓ | W41: VIRTUAL | X41: 46011 | Y41: DICIEMBRE | Z41: PRIMERA OPCIÓN
A42: 41 | B42: ROJAS ASCENCIO | C42: NATALY NICOLL | D42: 72868105 | E42: A261000950 | G42: natanicolet@gmail.com | H42: B | I42: PSICOLOGÍA | J42: Filial-Huacho | K42: ASISTIÓ | L42: 21 | M42: 0.84 | N42: 7 | O42: 0.7 | P42: 25 | Q42: 0.83333333 | R42: 32 | S42: 0.91428571 | T42: 85 | U42: 0.85 | V42: INGRESÓ | W42: VIRTUAL | X42: 46011 | Y42: DICIEMBRE | Z42: EXAMEN ORDINARIO
A43: 42 | B43: JARA LUTGARDO | C43: WILLIAM JAIR | D43: 73934005 | E43: A261000984 | G43: jairjaralutgardo@gmail.com | H43: B | I43: PSICOLOGÍA | J43: Filial-Huacho | K43: ASISTIÓ | L43: 20 | M43: 0.8 | N43: 8 | O43: 0.8 | P43: 26 | Q43: 0.86666667 | R43: 22 | S43: 0.62857143 | T43: 76 | U43: 0.76 | V43: INGRESÓ | W43: VIRTUAL | X43: 46011 | Y43: DICIEMBRE | Z43: EXAMEN ORDINARIO
A44: 43 | B44: NAZARIO YAURI | C44: FRANK ALEXIS | D44: 75384137 | E44: A261001071 | G44: aleexsummer@gmail.com | H44: B | I44: PSICOLOGÍA | J44: Filial-Huacho | K44: ASISTIÓ | L44: 15 | M44: 0.6 | N44: 6 | O44: 0.6 | P44: 16 | Q44: 0.53333333 | R44: 29 | S44: 0.82857143 | T44: 66 | U44: 0.66 | V44: INGRESÓ | W44: VIRTUAL | X44: 46011 | Y44: DICIEMBRE | Z44: EXAMEN ORDINARIO
A45: 44 | B45: SANDOVAL ACHIC | C45: DEYBI ANDRES | D45: 75467161 | E45: A261001267 | G45: deybixoo084@gmail.com | H45: B | I45: PSICOLOGÍA | J45: Filial-Huacho | K45: ASISTIÓ | L45: 13 | M45: 0.52 | N45: 4 | O45: 0.4 | P45: 21 | Q45: 0.7 | R45: 29 | S45: 0.82857143 | T45: 67 | U45: 0.67 | V45: INGRESÓ | W45: VIRTUAL | X45: 46011 | Y45: DICIEMBRE | Z45: EXAMEN ORDINARIO
...

Sheet Acta_Final_Chincha
A1: N° | B1: APELLIDOS | C1: NOMBRES | D1: DNI | E1: CODIGO | F1: TELEFONO | G1: CORREO | H1: AREA | I1: CARRERA | J1: SEDE DE ESTUDIO | K1: ASISTENCIA | L1: COMUNICACIÓN | M1: % | N1: H. COMUNICATIVAS | O1: % | P1: MATEMATICA | Q1: % | R1: CTA/CCSS | S1: % | T1: TOTAL (100 Pts) | U1: % | V1: CONDICIÓN | W1: MODALIDAD | X1: FECHA | Y1: EXAMEN | Z1: MODALIDAD DE INGRESO
A2: 1 | B2: HUAPAYA MORALES | C2: BENITO JOSE | D2: 43278412 | E2: A261000266 | G2: benito.huapaya.morales@gmail.com | H2: C | I2: ADMINISTRACIÓN DE EMPRESAS | J2: SEDE CHINCHA ALTA | K2: ASISTIÓ | L2: 15 | M2: 0.42857143 | N2: 5 | O2: 0.5 | P2: 12 | Q2: 0.4 | R2: 15 | S2: 0.6 | T2: 47 | U2: 0.47 | V2: INGRESÓ | W2: VIRTUAL | X2: 46011 | Y2: DICIEMBRE | Z2: EXAMEN ORDINARIO
A3: 2 | B3: NAZARIO YAURI | C3: REYNA KATHERIN | D3: 48052368 | E3: A261001183 | G3: katty.270613@gmail.com | H3: C | I3: ADMINISTRACIÓN DE EMPRESAS | J3: Filial-Huacho | K3: ASISTIÓ | L3: 22 | M3: 0.62857143 | N3: 9 | O3: 0.9 | P3: 25 | Q3: 0.83333333 | R3: 22 | S3: 0.88 | T3: 78 | U3: 0.78 | V3: INGRESÓ | W3: VIRTUAL | X3: 46011 | Y3: DICIEMBRE | Z3: EXAMEN ORDINARIO
A4: 3 | B4: CCAULLA SULCA | C4: WILMA | D4: 60324145 | E4: A261001177 | G4: 14vilmasulca@gmail.com | H4: C | I4: ADMINISTRACIÓN DE EMPRESAS | J4: SEDE CHINCHA ALTA | K4: ASISTIÓ | L4: 18 | M4: 0.51428571 | N4: 5 | O4: 0.5 | P4: 8 | Q4: 0.26666667 | R4: 5 | S4: 0.2 | T4: 36 | U4: 0.36 | V4: INGRESÓ | W4: VIRTUAL | X4: 46011 | Y4: DICIEMBRE | Z4: EXAMEN ORDINARIO
A5: 4 | B5: OYOLA RAMIREZ | C5: DEREK FABRICIO | D5: 60328822 | E5: A261001209 | G5: derek.or.2023@gmail.com | H5: C | I5: ADMINISTRACIÓN DE EMPRESAS | J5: Filial-Huacho | K5: ASISTIÓ | L5: 26 | M5: 0.74285714 | N5: 7 | O5: 0.7 | P5: 16 | Q5: 0.53333333 | R5: 22 | S5: 0.88 | T5: 71 | U5: 0.71 | V5: INGRESÓ | W5: VIRTUAL | X5: 46011 | Y5: DICIEMBRE | Z5: EXAMEN ORDINARIO
A6: 5 | B6: OSCATE SANCHEZ | C6: BRENDALY GRACIELA | D6: 60558991 | E6: A261001084 | G6: oscatebrenda@gmail.com | H6: C | I6: ADMINISTRACIÓN DE EMPRESAS | J6: Filial-Huacho | K6: ASISTIÓ | L6: 23 | M6: 0.65714286 | N6: 9 | O6: 0.9 | P6: 22 | Q6: 0.73333333 | R6: 18 | S6: 0.72 | T6: 72 | U6: 0.72 | V6: INGRESÓ | W6: VIRTUAL | X6: 46011 | Y6: DICIEMBRE | Z6: EXAMEN ORDINARIO
A7: 6 | B7: ROMAN JAIMES | C7: JESUS SEBASTIAN | D7: 60649663 | E7: A261001080 | G7: jesusromanjaimes01@gmail.com | H7: C | I7: ADMINISTRACIÓN DE EMPRESAS | J7: Filial-Huacho | K7: ASISTIÓ | L7: 24 | M7: 0.68571429 | N7: 9 | O7: 0.9 | P7: 24 | Q7: 0.8 | R7: 17 | S7: 0.68 | T7: 74 | U7: 0.74 | V7: INGRESÓ | W7: VIRTUAL | X7: 46011 | Y7: DICIEMBRE | Z7: PRIMERA OPCIÓN
A8: 7 | B8: ROSADIO MEDINA | C8: JOHN ALDAIR | D8: 60686411 | E8: A261001019 | G8: johnrosadio27@gmail.com | H8: C | I8: ADMINISTRACIÓN DE EMPRESAS | J8: Filial-Huacho | K8: ASISTIÓ | L8: 27 | M8: 0.77142857 | N8: 9 | O8: 0.9 | P8: 21 | Q8: 0.7 | R8: 21 | S8: 0.84 | T8: 78 | U8: 0.78 | V8: INGRESÓ | W8: VIRTUAL | X8: 46011 | Y8: DICIEMBRE | Z8: PRIMERA OPCIÓN
A9: 8 | B9: SISTERNA RAMIREZ | C9: JOSE ROLANDO RYU | D9: 60686417 | E9: A261001121 | G9: joserolandoryusisternaramirez@gmail.com | H9: C | I9: ADMINISTRACIÓN DE EMPRESAS | J9: Filial-Huacho | K9: ASISTIÓ | L9: 25 | M9: 0.71428571 | N9: 8 | O9: 0.8 | P9: 27 | Q9: 0.9 | R9: 20 | S9: 0.8 | T9: 80 | U9: 0.8 | V9: INGRESÓ | W9: VIRTUAL | X9: 46011 | Y9: DICIEMBRE | Z9: PRIMERA OPCIÓN
A10: 9 | B10: GUILLEN NONATO | C10: YASSADI PAOLA | D10: 61113462 | E10: A261001282 | G10: yassadi286@gmail.com | H10: C | I10: ADMINISTRACIÓN DE EMPRESAS | J10: Filial-Huacho | K10: ASISTIÓ | L10: 23 | M10: 0.65714286 | N10: 7 | O10: 0.7 | P10: 20 | Q10: 0.66666667 | R10: 15 | S10: 0.6 | T10: 65 | U10: 0.65 | V10: INGRESÓ | W10: VIRTUAL | X10: 46011 | Y10: DICIEMBRE | Z10: EXAMEN ORDINARIO
A11: 10 | B11: CANO MILLA | C11: LILIANA CECILIA | D11: 61506024 | E11: A261000867 | G11: luli.lila.28cici@gmail.com | H11: C | I11: ADMINISTRACIÓN DE EMPRESAS | J11: Filial-Huacho | K11: ASISTIÓ | L11: 13 | M11: 0.37142857 | N11: 6 | O11: 0.6 | P11: 12 | Q11: 0.4 | R11: 7 | S11: 0.28 | T11: 38 | U11: 0.38 | V11: INGRESÓ | W11: VIRTUAL | X11: 46011 | Y11: DICIEMBRE | Z11: PRIMERA OPCIÓN
A12: 11 | B12: RODRIGUEZ AGUILAR | C12: JULIA ISABELLA | D12: 61506141 | E12: A261001160 | G12: juliaisabella09102008@gmail.com | H12: C | I12: ADMINISTRACIÓN DE EMPRESAS | J12: Filial-Huacho | K12: ASISTIÓ | L12: 23 | M12: 0.65714286 | N12: 9 | O12: 0.9 | P12: 19 | Q12: 0.63333333 | R12: 13 | S12: 0.52 | T12: 64 | U12: 0.64 | V12: INGRESÓ | W12: VIRTUAL | X12: 46011 | Y12: DICIEMBRE | Z12: PRIMERA OPCIÓN
A13: 12 | B13: DAVILA NIETO | C13: MIGUEL ANGEL | D13: 61680824 | E13: A261001222 | G13: davilapaola073@gmail.com | H13: C | I13: ADMINISTRACIÓN DE EMPRESAS | J13: Filial-Huacho | K13: ASISTIÓ | L13: 7 | M13: 0.2 | N13: 4 | O13: 0.4 | P13: 10 | Q13: 0.33333333 | R13: 10 | S13: 0.4 | T13: 31 | U13: 0.31 | V13: INGRESÓ | W13: VIRTUAL | X13: 46011 | Y13: DICIEMBRE | Z13: PRIMERA OPCIÓN
... A40: 39 | B40: GIRALDO JUSTINO | C40: BRITHANNY HARLEY | D40: 60459269 | E40: A261001236 | G40: harleyjustino2006@gmail.com | H40: B | I40: ENFERMERÍA | J40: Filial-Huacho | K40: ASISTIÓ | L40: 20 | M40: 0.8 | N40: 7 | O40: 0.7 | P40: 23 | Q40: 0.76666667 | R40: 33 | S40: 0.94285714 | T40: 83 | U40: 0.83 | V40: INGRESÓ | W40: VIRTUAL | X40: 46011 | Y40: DICIEMBRE | Z40: EXAMEN ORDINARIO
A41: 40 | B41: ACEVEDO GUEVARA | C41: YHADIRA MICHELLE | D41: 60577442 | E41: A261000900 | F41: 996186698 | G41: isabelhuertas507@gmail.com | H41: B | I41: ENFERMERÍA | J41: Filial-Huacho | K41: ASISTIÓ | L41: 10 | M41: 0.4 | N41: 6 | O41: 0.6 | P41: 17 | Q41: 0.56666667 | R41: 27 | S41: 0.77142857 | T41: 60 | U41: 0.6 | V41: INGRESÓ | W41: VIRTUAL | X41: 46011 | Y41: DICIEMBRE | Z41: EXAMEN ORDINARIO
A42: 41 | B42: CHAVEZ SALVADOR | C42: ROSALINDA NATALIA | D42: 60650008 | E42: A261001205 | G42: rosalindachavezsalvador7@gmail.com | H42: B | I42: ENFERMERÍA | J42: Filial-Huacho | K42: ASISTIÓ | L42: 17 | M42: 0.68 | N42: 8 | O42: 0.8 | P42: 27 | Q42: 0.9 | R42: 32 | S42: 0.91428571 | T42: 84 | U42: 0.84 | V42: INGRESÓ | W42: VIRTUAL | X42: 46011 | Y42: DICIEMBRE | Z42: PRIMERA OPCIÓN
A43: 42 | B43: FLORES MEZA | C43: JACKELINE FIORELLA | D43: 61035075 | E43: A261001113 | G43: fiorelaflores701@gmail.com | H43: B | I43: ENFERMERÍA | J43: Filial-Huacho | K43: ASISTIÓ | L43: 11 | M43: 0.44 | N43: 5 | O43: 0.5 | P43: 20 | Q43: 0.66666667 | R43: 25 | S43: 0.71428571 | T43: 61 | U43: 0.61 | V43: INGRESÓ | W43: VIRTUAL | X43: 46011 | Y43: DICIEMBRE | Z43: EXAMEN ORDINARIO
A44: 43 | B44: ORTIZ PASCUAL | C44: ARIANA EDELINA | D44: 61062460 | E44: A261001233 | G44: arianaortizpascual@gmail.com | H44: B | I44: ENFERMERÍA | J44: Filial-Huacho | K44: ASISTIÓ | L44: 17 | M44: 0.68 | N44: 7 | O44: 0.7 | P44: 15 | Q44: 0.5 | R44: 23 | S44: 0.65714286 | T44: 62 | U44: 0.62 | V44: INGRESÓ | W44: VIRTUAL | X44: 46011 | Y44: DICIEMBRE | Z44: EXAMEN ORDINARIO
A45: 44 | B45: ZAVALETA CASTILLO | C45: STHEFANI YASHURI | D45: 61113531 | E45: A261000898 | G45: sthefanyzavaleta74@gmail.com | H45: B | I45: ENFERMERÍA | J45: Filial-Huacho | K45: ASISTIÓ | L45: 13 | M45: 0.52 | N45: 5 | O45: 0.5 | P45: 11 | Q45: 0.36666667 | R45: 24 | S45: 0.68571429 | T45: 53 | U45: 0.53 | V45: INGRESÓ | W45: VIRTUAL | X45: 46011 | Y45: DICIEMBRE | Z45: EXAMEN ORDINARIO
A46: 45 | B46: ROMERO AIRA | C46: JUAN DAVID | D46: 61369069 | E46: A261001217 | G46: shetosbv16@gmail.com | H46: B | I46: ENFERMERÍA | J46: Filial-Huacho | K46: ASISTIÓ | L46: 17 | M46: 0.68 | N46: 8 | O46: 0.8 | P46: 25 | Q46: 0.83333333 | R46: 30 | S46: 0.85714286 | T46: 80 | U46: 0.8 | V46: INGRESÓ | W46: VIRTUAL | X46: 46011 | Y46: DICIEMBRE | Z46: PRIMERA OPCIÓN
A47: 46 | B47: SANDOVAL FLORES | C47: JULIETA DEL CARMEN | D47: 61505762 | E47: A261001027 | G47: irmafloresbartolome@gmail.com | H47: B | I47: ENFERMERÍA | J47: Filial-Huacho | K47: ASISTIÓ | L47: 16 | M47: 0.64 | N47: 7 | O47: 0.7 | P47: 17 | Q47: 0.56666667 | R47: 29 | S47: 0.82857143 | T47: 69 | U47: 0.69 | V47: INGRESÓ | W47: VIRTUAL | X47: 46011 | Y47: DICIEMBRE | Z47: PRIMERA OPCIÓN
A48: 47 | B48: ROBLES CARQUIN | C48: GRACE ABIGAIL BRESHITH | D48: 61506255 | E48: A261001280 | G48: graceroblescarquin0110@gmail.com | H48: B | I48: ENFERMERÍA | J48: Filial-Huacho | K48: ASISTIÓ | L48: 5 | M48: 0.2 | N48: 4 | O48: 0.4 | P48: 13 | Q48: 0.43333333 | R48: 28 | S48: 0.8 | T48: 50 | U48: 0.5 | V48: INGRESÓ | W48: VIRTUAL | X48: 46011 | Y48: DICIEMBRE | Z48: PRIMERA OPCIÓN
A49: 48 | B49: CHUMBES ZENOZAIN | C49: CARLOS SEBASTIAN | D49: 71894777 | E49: A261000964 | G49: sebastianzenozain038@gmail.com | H49: B | I49: ENFERMERÍA | J49: Filial-Huacho | K49: ASISTIÓ | L49: 14 | M49: 0.56 | N49: 8 | O49: 0.8 | P49: 16 | Q49: 0.53333333 | R49: 26 | S49: 0.74285714 | T49: 64 | U49: 0.64 | V49: INGRESÓ | W49: VIRTUAL | X49: 46011 | Y49: DICIEMBRE | Z49: EXAMEN ORDINARIO
A50: 49 | B50: TOLENTINO SERPA | C50: ANGIE NYCOLE | D50: 75978308 | E50: A261000963 | G50: serpaangie@gmail.com | H50: B | I50: ENFERMERÍA | J50: Filial-Huacho | K50: ASISTIÓ | L50: 17 | M50: 0.68 | N50: 8 | O50: 0.8 | P50: 26 | Q50: 0.86666667 | R50: 35 | S50: 1 | T50: 86 | U50: 0.86 | V50: INGRESÓ | W50: VIRTUAL | X50: 46011 | Y50: DICIEMBRE | Z50: EXAMEN ORDINARIO
A51: 50 | B51: ORTIZ RAMOS | C51: SAMIRA VIVIANA | D51: 76345536 | E51: A261000943 | G51: samiraortizramos25@gmail.com | H51: B | I51: ENFERMERÍA | J51: Filial-Huacho | K51: ASISTIÓ | L51: 20 | M51: 0.8 | N51: 8 | O51: 0.8 | P51: 11 | Q51: 0.36666667 | R51: 32 | S51: 0.91428571 | T51: 71 | U51: 0.71 | V51: INGRESÓ | W51: VIRTUAL | X51: 46011 | Y51: DICIEMBRE | Z51: EXAMEN ORDINARIO
A52: 51 | B52: BAEZ VELASQUEZ | C52: NINOSSCKA YAMILETH PAOLA | D52: 61171572 | E52: A261001034 | G52: yamiletbaez300@gmail.com | H52: A | I52: INGENIERÍA INDUSTRIAL | J52: SEDE CHINCHA ALTA | K52: ASISTIÓ | L52: 14 | M52: 0.56 | N52: 9 | O52: 0.9 | P52: 21 | Q52: 0.42 | R52: 12 | S52: 0.8 | T52: 56 | U52: 0.56 | V52: INGRESÓ | W52: VIRTUAL | X52: 46011 | Y52: DICIEMBRE | Z52: EXAMEN ORDINARIO
A53: 52 | B53: NAPUCHI MANIHUARI | C53: KATTYA | D53: 63358468 | E53: A261000910 | G53: kattyanapuchi@gmail.com | H53: A | I53: INGENIERÍA INDUSTRIAL | J53: SEDE CHINCHA ALTA | K53: ASISTIÓ | L53: 11 | M53: 0.44 | N53: 6 | O53: 0.6 | P53: 36 | Q53: 0.72 | R53: 13 | S53: 0.86666667 | T53: 66 | U53: 0.66 | V53: INGRESÓ | W53: VIRTUAL | X53: 46011 | Y53: DICIEMBRE | Z53: EXAMEN ORDINARIO
... A63: 62 | B63: ROMAN UNZUETA | C63: MASSIEL ANDREA | D63: 61565276 | E63: A261000986 | G63: andrearomanunzueta036@gmail.com | H63: B | I63: OBSTETRICIA | J63: Filial-Huacho | K63: ASISTIÓ | L63: 17 | M63: 0.68 | N63: 7 | O63: 0.7 | P63: 26 | Q63: 0.86666667 | R63: 29 | S63: 0.82857143 | T63: 79 | U63: 0.79 | V63: INGRESÓ | W63: VIRTUAL | X63: 46011 | Y63: DICIEMBRE | Z63: PRIMERA OPCIÓN
A64: 63 | B64: LEON CHINCHAY | C64: GERAME DENNIS | D64: 75108509 | E64: A261000871 | F64: 905612939 | G64: leongerami10@gmail.com | H64: B | I64: OBSTETRICIA | J64: Filial-Huacho | K64: ASISTIÓ | L64: 16 | M64: 0.64 | N64: 5 | O64: 0.5 | P64: 24 | Q64: 0.8 | R64: 31 | S64: 0.88571429 | T64: 76 | U64: 0.76 | V64: INGRESÓ | W64: VIRTUAL | X64: 46011 | Y64: DICIEMBRE | Z64: EXAMEN ORDINARIO
A65: 64 | B65: ROMERO LLAGAS | C65: NICOLE NASAY | D65: 75975765 | E65: A261000897 | G65: nasayromerollagas@gmail.com | H65: B | I65: OBSTETRICIA | J65: Filial-Huacho | K65: ASISTIÓ | L65: 11 | M65: 0.44 | N65: 7 | O65: 0.7 | P65: 10 | Q65: 0.33333333 | R65: 30 | S65: 0.85714286 | T65: 58 | U65: 0.58 | V65: INGRESÓ | W65: VIRTUAL | X65: 46011 | Y65: DICIEMBRE | Z65: EXAMEN ORDINARIO
A66: 65 | B66: AURIS ANDRES | C66: NAYDU EVELYN | D66: 47351249 | E66: A261000955 | G66: nayduaurisandres20@gmail.com | H66: B | I66: PSICOLOGÍA | J66: Filial-Huacho | K66: ASISTIÓ | L66: 19 | M66: 0.76 | N66: 9 | O66: 0.9 | P66: 13 | Q66: 0.43333333 | R66: 15 | S66: 0.42857143 | T66: 56 | U66: 0.56 | V66: INGRESÓ | W66: VIRTUAL | X66: 46011 | Y66: DICIEMBRE | Z66: EXAMEN ORDINARIO
A67: 66 | B67: RAMIREZ LLIQUE | C67: SANDRA CORINA | D67: 48111510 | E67: A261001259 | G67: sandracorina30@gmail.com | H67: B | I67: PSICOLOGÍA | J67: Filial-Huacho | K67: ASISTIÓ | L67: 13 | M67: 0.52 | N67: 6 | O67: 0.6 | P67: 13 | Q67: 0.43333333 | R67: 28 | S67: 0.8 | T67: 60 | U67: 0.6 | V67: INGRESÓ | W67: VIRTUAL | X67: 46011 | Y67: DICIEMBRE | Z67: EXAMEN ORDINARIO
A68: 67 | B68: MELGAR MEDINA | C68: LUCIANA LISET | D68: 60195925 | E68: A261001277 | G68: lucymelgmed@gmail.com | H68: B | I68: PSICOLOGÍA | J68: Filial-Huacho | K68: ASISTIÓ | L68: 8 | M68: 0.32 | N68: 8 | O68: 0.8 | P68: 23 | Q68: 0.76666667 | R68: 13 | S68: 0.37142857 | T68: 52 | U68: 0.52 | V68: INGRESÓ | W68: VIRTUAL | X68: 46011 | Y68: DICIEMBRE | Z68: EXAMEN ORDINARIO
A69: 68 | B69: SIGUEÑAS BEDON | C69: HELEN YASHURIN | D69: 60405475 | E69: A261001005 | G69: helenyashurinsiguenasbedon@gmail.com | H69: B | I69: PSICOLOGÍA | J69: Filial-Huacho | K69: ASISTIÓ | L69: 17 | M69: 0.68 | N69: 8 | O69: 0.8 | P69: 23 | Q69: 0.76666667 | R69: 29 | S69: 0.82857143 | T69: 77 | U69: 0.77 | V69: INGRESÓ | W69: VIRTUAL | X69: 46011 | Y69: DICIEMBRE | Z69: PRIMERA OPCIÓN
A70: 69 | B70: FELIX MENDOZA | C70: DULCE INES | D70: 60584671 | E70: A261001161 | G70: inesmid15@gmail.com | H70: B | I70: PSICOLOGÍA | J70: Filial-Huacho | K70: ASISTIÓ | L70: 12 | M70: 0.48 | N70: 8 | O70: 0.8 | P70: 23 | Q70: 0.76666667 | R70: 23 | S70: 0.65714286 | T70: 66 | U70: 0.66 | V70: INGRESÓ | W70: VIRTUAL | X70: 46011 | Y70: DICIEMBRE | Z70: EXAMEN ORDINARIO
A71: 70 | B71: BECERRA QUIÑONEZ | C71: EVER DAVID | D71: 60620325 | E71: A261000935 | G71: everdavidbecerra@gmail.com | H71: B | I71: PSICOLOGÍA | J71: Filial-Huacho | K71: ASISTIÓ | L71: 16 | M71: 0.64 | N71: 8 | O71: 0.8 | P71: 6 | Q71: 0.2 | R71: 12 | S71: 0.34285714 | T71: 42 | U71: 0.42 | V71: INGRESÓ | W71: VIRTUAL | X71: 46011 | Y71: DICIEMBRE | Z71: PRIMERA OPCIÓN
A72: 71 | B72: TASAYCO ROJAS | C72: AIKO VICTORIA | D72: 60620334 | E72: A261001070 | G72: victoriatasayco.14@gmail.com | H72: B | I72: PSICOLOGÍA | J72: Filial-Huacho | K72: ASISTIÓ | L72: 19 | M72: 0.76 | N72: 8 | O72: 0.8 | P72: 20 | Q72: 0.66666667 | R72: 29 | S72: 0.82857143 | T72: 76 | U72: 0.76 | V72: INGRESÓ | W72: VIRTUAL | X72: 46011 | Y72: DICIEMBRE | Z72: PRIMERA OPCIÓN
A73: 72 | B73: BISSO DE LOS SANTOS | C73: AIXA ESTEFANIA | D73: 60650142 | E73: A261001010 | G73: aixab036@gmail.com | H73: B | I73: PSICOLOGÍA | J73: Filial-Huacho | K73: ASISTIÓ | L73: 19 | M73: 0.76 | N73: 9 | O73: 0.9 | P73: 29 | Q73: 0.96666667 | R73: 29 | S73: 0.82857143 | T73: 86 | U73: 0.86 | V73: INGRESÓ | W73: VIRTUAL | X73: 46011 | Y73: DICIEMBRE | Z73: PRIMERA OPCIÓN
A74: 73 | B74: RAMOS LLAGAS | C74: STEFANIE GERALDINE | D74: 60803824 | E74: A261000146 | G74: geraldineyoriana@gmail.com | H74: B | I74: PSICOLOGÍA | J74: FILIAL HUAURA | K74: ASISTIÓ | L74: 17 | M74: 0.68 | N74: 7 | O74: 0.7 | P74: 18 | Q74: 0.6 | R74: 31 | S74: 0.88571429 | T74: 73 | U74: 0.73 | V74: INGRESÓ | W74: VIRTUAL | X74: 46011 | Y74: DICIEMBRE | Z74: EXAMEN ORDINARIO
A75: 74 | B75: CUBAS AREVALO | C75: ERIKA ANGELIQUE | D75: 61062624 | E75: A261000931 | G75: erika2018cubas@gmail.com | H75: B | I75: PSICOLOGÍA | J75: Filial-Huacho | K75: ASISTIÓ | L75: 17 | M75: 0.68 | N75: 6 | O75: 0.6 | P75: 22 | Q75: 0.73333333 | R75: 31 | S75: 0.88571429 | T75: 76 | U75: 0.76 | V75: INGRESÓ | W75: VIRTUAL | X75: 46011 | Y75: DICIEMBRE | Z75: EXAMEN ORDINARIO
...

Sheet Datos
A1: DNI | B1: AREA | C1: MODALIDAD DE INGRESO | D1: NOMBRES | E1: APELLIDOS | F1: CODIGO | G1: TELEFONO | H1: CORREO
A2: 60584665 | C2: PROM - ENF. Y ARQUIT. - ORDINARIO (100% DCTO) | D2: YAMILEHT SOFIA | E2: GUILLEN ROSAS | F2: A252000007 | G2: 9129077007 | H2: sofia.acuarelita@gmail.com
A3: 61747247 | C3: GENERAL - ORDINARIO (30% DCTO) | D3: KEVIN LEONEL | E3: SOLORZANO HUAYTAN | F3: A252000078 | G3: 927435622 | H3: solorzano24kevin@gmail.com
A4: 79950632 | C4: GENERAL - ORDINARIO (30% DCTO) | D4: JOSE DARIO LALILIVIO | E4: SANCHEZ BRAVO | F4: A252000079 | G4: 907254866 | H4: darsanchez134@gmail.com, rosmeribravo@hotmail.com
A5: 71918593 | C5: PROM - ENF. Y ARQUIT. - ORDINARIO (100% DCTO) | D5: JOEL ANGELLO | E5: DOMINGUEZ MARQUEZ | F5: A252000108 | G5: 976279321 | H5: angello_dominguez_@hotmail.com, angellodominguez15@gmail.com
A6: 60745483 | C6: PROM - ENF. Y ARQUIT. - ORDINARIO (100% DCTO) | D6: ROGER GIANPIERE | E6: MAYO AYALA | F6: A252000113 | G6: 964265848 | H6: nicolasayala18pe@gmail.com
A7: 60209971 | C7: PROM - ENF. Y ARQUIT. - ORDINARIO (100% DCTO) | D7: THALIA ESTHEFANY | E7: LOPEZ PASCUAL | F7: A252000177 | G7: 970201561 | H7: thalialopez750@gmail.com
A8: 71448858 | C8: GENERAL - ORDINARIO (30% DCTO) | D8: LIMSAY ANDREA | E8: BERNAL QUINTEROS | F8: A252000207 | G8: 946465108 | H8: limsay_27@hotmail.com
A9: 71957612 | C9: GENERAL - ORDINARIO (30% DCTO) | D9: THALIA LUCERO | E9: MOSQUERA SAMANAMUD | F9: A252000209 | G9: 958469815 | H9: tlmosquerasama@gmail.com
A10: 75364805 | C10: GENERAL - ORDINARIO (30% DCTO) | D10: JAZMINE JENNIFFER | E10: MAZA GARCIA | F10: A252000212 | G10: 967153853 | H10: garciastone@hotmail.com
A11: 73874633 | C11: JUNIO - ENFER. Y ARQUITC. - ORDINARIO | D11: VALERIA ALEJANDRA | E11: MAZA SOLORZANO | F11: A252000284 | G11: 992778190 | H11: valeriaalejandramaza@gmail.com
A12: 60797365 | C12: PROM - GENERAL - ORDINARIO (100% DCTO) | D12: ALISON JOVANA | E12: ASCENCIO RAMIREZ | F12: A252000326 | G12: 904133460 | H12: ascencioalison2@gmail.com
A13: 73259401 | C13: PROM - GENERAL - ORDINARIO (100% DCTO) | D13: JORGE LUIS | E13: SILVA QUISPE | F13: A252000384 | G13: 916039955 | H13: j.luissilva427@gmail.com
... A91: 23984656 | C91: A DISTANCIA - GENERAL - ORDINARIO - PROM | D91: MARTHA RAQUEL | E91: GUILLEN PENA | F91: A252000328 | G91: 991044561 | H91: guillenpear@yahoo.com
A92: 00320212 | C92: A DISTANCIA - GENERAL - ORDINARIO - PROM | D92: HENRRY SIGIFREDO | E92: ERAS MONTOYA | F92: A252000421 | G92: 935226787 | H92: polieras1164@gmail.com
A93: 42913641 | C93: A DISTANCIA - GENERAL - ORDINARIO - PROM | D93: HILDA ALICIA | E93: RIMAC MEDINA | F93: A252000510 | G93: 961430520 | H93: hildaaliciarimacmedina@gmail.com
A94: 60777931 | C94: A DISTANCIA - GENERAL - ORDINARIO - PROM | D94: URTEAGA LIBBY ANTUANETTE | E94: CACERES SAM | F94: A252000627 | G94: 970705831 | H94: libbyurteaga@gmail.com
A95: 46741192 | C95: A DISTANCIA - GENERAL - ORDINARIO - PROM | D95: BASILIO APOLINARIO | E95: OROCHE GUTIERREZ | F95: A252000629 | G95: 974404727 | H95: gutierrezob@gmail.com
A96: 40524243 | C96: A DISTANCIA - GENERAL - ORDINARIO - PROM | D96: NEIBY YHOJANA | E96: URTEAGA QUEZADA | F96: A252000631 | G96: 931761676 | H96: neiby_04_04@hotmail.com
A97: 21863556 | C97: A DISTANCIA - GENERAL - ORDINARIO - PROM | D97: JOSE MANUEL | E97: TASAYCO TORRES | F97: A252000649 | G97: 950779982 | H97: moritasayco39041973@gmail.com
A98: 42720410 | C98: A DISTANCIA - GENERAL - ORDINARIO - PROM | D98: PABLO CESAR | E98: RUIZ CHERO | F98: A252000668 | G98: 968772565, 992622529 | H98: cesar_ch3@hotmail.com
A99: 71061962 | C99: A DISTANCIA - GENERAL - ORDINARIO | D99: RAUL MARTIN | E99: CONDO ARENAS | F99: A252000682 | G99: 963414134 | H99: gamersoteop7@hotmail.com
A100: 60886660 | C100: A DISTANCIA - GENERAL - ORDINARIO - PROM | D100: FLAVIO | E100: CHUQUISPUMA TAPIA | F100: A252000701 | G100: 980657958 | H100: flaviotapia2018@gmail.com
A101: 78105587 | C101: A DISTANCIA - GENERAL - ORDINARIO - PROM | D101: LEONEL JEREMY | E101: ROSAS SALGUERON | F101: A252000702 | G101: 920063869 | H101: jrosassalgueron@gmail.com
A102: 45356308 | C102: PROM - GENERAL - ORDINARIO (100% DCTO) | D102: RONALD ERICK | E102: VILCA ESTEBAN | F102: A252000710 | G102: 955571334, 937325164 | H102: pegasoesteban2@gmail.com
A103: 46709229 | C103: A DISTANCIA - GENERAL - ORDINARIO | D103: HELBERT ROMER | E103: FLORES AGUILAR | F103: A252000717 | G103: 989649098 | H103: helbert2711@gmail.com
A104: 61144951 | C104: A DISTANCIA - GENERAL - ORDINARIO - PROM | D104: ORLANDO DAVID | E104: VERASTEGUI LOPEZ | F104: A252000718 | G104: 931883724 | H104: davidlopez13111@gmail.com
... A143: 73359671 | C143: A DISTANCIA - GENERAL - ORDINARIO - PROM | D143: LEIDY SELENA | E143: AGUERO RAMOS | F143: A252001083 | G143: 991481268 | H143: agueroramosselena@gmail.com

Sheet Hoja2
I1: 1
A2: 1 | B2: =VLOOKUP(D2,Datos!$A$1:$H$256,4,FALSE) -> #N/A | C2: =VLOOKUP(D2,Datos!$A$1:$H$256,5,FALSE) -> #N/A | D2: 60930028 | E2: =VLOOKUP(D2,Datos!$A$1:$H$256,6,FALSE) -> #N/A | F2: =VLOOKUP(D2,Datos!$A$1:$H$256,7,FALSE) -> #N/A | G2: =VLOOKUP(D2,Datos!$A$1:$H$256,8,FALSE) -> #N/A | H2: A | I2: INGENIERIA INDUSTRIAL | J2: SEDE CHINCHA | K2: ASISTIÓ | L2: 11 | M2: =IF(L2="","",(L2/25)) -> 0.44 | N2: 10 | O2: =IF(N2="","",(N2/10)) -> 1 | P2: 17 | Q2: =IF(P2="","",(P2/50)) -> 0.34 | R2: 3 | S2: =IF(R2="","",(R2/15)) -> 0.2 | T2: =L2+N2+P2+R2 -> 41 | U2: =IF(T2="","",(T2/100)) -> 0.41 | V2: =IF(U2=0,"NO INGRESÓ","INGRESÓ") -> INGRESÓ | W2: PRESENCIAL | X2: 45745 | Y2: MARZO | Z2: =VLOOKUP(D2,Datos!$A$1:$C$256,3,FALSE) -> #N/A
A3: 2 | B3: =VLOOKUP(D3,Datos!$A$1:$H$256,4,FALSE) -> #N/A | C3: =VLOOKUP(D3,Datos!$A$1:$H$256,5,FALSE) -> #N/A | D3: 75018255 | E3: =VLOOKUP(D3,Datos!$A$1:$H$256,6,FALSE) -> #N/A | F3: =VLOOKUP(D3,Datos!$A$1:$H$256,7,FALSE) -> #N/A | G3: =VLOOKUP(D3,Datos!$A$1:$H$256,8,FALSE) -> #N/A | H3: A | I3: INGENIERIA INDUSTRIAL | J3: SEDE CHINCHA | K3: ASISTIÓ | L3: 14 | M3: =IF(L3="","",(L3/25)) -> 0.56 | N3: 8 | O3: =IF(N3="","",(N3/10)) -> 0.8 | P3: 17 | Q3: =IF(P3="","",(P3/50)) -> 0.34 | R3: 7 | S3: =IF(R3="","",(R3/15)) -> 0.46666667 | T3: =L3+N3+P3+R3 -> 46 | U3: =IF(T3="","",(T3/100)) -> 0.46 | V3: =IF(U3=0,"NO INGRESÓ","INGRESÓ") -> INGRESÓ | W3: PRESENCIAL | X3: 45745 | Y3: MARZO | Z3: =VLOOKUP(D3,Datos!$A$1:$C$256,3,FALSE) -> #N/A
A4: 3 | B4: =VLOOKUP(D4,Datos!$A$1:$H$256,4,FALSE) -> #N/A | C4: =VLOOKUP(D4,Datos!$A$1:$H$256,5,FALSE) -> #N/A | D4: 71430099 | E4: =VLOOKUP(D4,Datos!$A$1:$H$256,6,FALSE) -> #N/A | F4: =VLOOKUP(D4,Datos!$A$1:$H$256,7,FALSE) -> #N/A | G4: =VLOOKUP(D4,Datos!$A$1:$H$256,8,FALSE) -> #N/A | H4: A | I4: INGENIERIA CIVIL | J4: SEDE CHINCHA | K4: ASISTIÓ | L4: 9 | M4: =IF(L4="","",(L4/25)) -> 0.36 | N4: 8 | O4: =IF(N4="","",(N4/10)) -> 0.8 | P4: 25 | Q4: =IF(P4="","",(P4/50)) -> 0.5 | R4: 5 | S4: =IF(R4="","",(R4/15)) -> 0.33333333 | T4: =L4+N4+P4+R4 -> 47 | U4: =IF(T4="","",(T4/100)) -> 0.47 | V4: =IF(U4=0,"NO INGRESÓ","INGRESÓ") -> INGRESÓ | W4: PRESENCIAL | X4: 45745 | Y4: MARZO | Z4: =VLOOKUP(D4,Datos!$A$1:$C$256,3,FALSE) -> #N/A
A5: 4 | B5: =VLOOKUP(D5,Datos!$A$1:$H$256,4,FALSE) -> #N/A | C5: =VLOOKUP(D5,Datos!$A$1:$H$256,5,FALSE) -> #N/A | D5: 61247481 | E5: =VLOOKUP(D5,Datos!$A$1:$H$256,6,FALSE) -> #N/A | F5: =VLOOKUP(D5,Datos!$A$1:$H$256,7,FALSE) -> #N/A | G5: =VLOOKUP(D5,Datos!$A$1:$H$256,8,FALSE) -> #N/A | H5: A | I5: INGENIERIA CIVIL | J5: SEDE CHINCHA | K5: ASISTIÓ | L5: 10 | M5: =IF(L5="","",(L5/25)) -> 0.4 | N5: 7 | O5: =IF(N5="","",(N5/10)) -> 0.7 | P5: 10 | Q5: =IF(P5="","",(P5/50)) -> 0.2 | R5: 3 | S5: =IF(R5="","",(R5/15)) -> 0.2 | T5: =L5+N5+P5+R5 -> 30 | U5: =IF(T5="","",(T5/100)) -> 0.3 | V5: =IF(U5=0,"NO INGRESÓ","INGRESÓ") -> INGRESÓ | W5: PRESENCIAL | X5: 45745 | Y5: MARZO | Z5: =VLOOKUP(D5,Datos!$A$1:$C$256,3,FALSE) -> #N/A
A6: 5 | B6: =VLOOKUP(D6,Datos!$A$1:$H$256,4,FALSE) -> #N/A | C6: =VLOOKUP(D6,Datos!$A$1:$H$256,5,FALSE) -> #N/A | D6: 60984879 | E6: =VLOOKUP(D6,Datos!$A$1:$H$256,6,FALSE) -> #N/A | F6: =VLOOKUP(D6,Datos!$A$1:$H$256,7,FALSE) -> #N/A | G6: =VLOOKUP(D6,Datos!$A$1:$H$256,8,FALSE) -> #N/A | H6: A | I6: INGENIERIA DE SISTEMAS | J6: SEDE CHINCHA | K6: ASISTIÓ | L6: 13 | M6: =IF(L6="","",(L6/25)) -> 0.52 | N6: 7 | O6: =IF(N6="","",(N6/10)) -> 0.7 | P6: 18 | Q6: =IF(P6="","",(P6/50)) -> 0.36 | R6: 6 | S6: =IF(R6="","",(R6/15)) -> 0.4 | T6: =L6+N6+P6+R6 -> 44 | U6: =IF(T6="","",(T6/100)) -> 0.44 | V6: =IF(U6=0,"NO INGRESÓ","INGRESÓ") -> INGRESÓ | W6: PRESENCIAL | X6: 45745 | Y6: MARZO | Z6: =VLOOKUP(D6,Datos!$A$1:$C$256,3,FALSE) -> #N/A
A7: 6 | B7: =VLOOKUP(D7,Datos!$A$1:$H$256,4,FALSE) -> #N/A | C7: =VLOOKUP(D7,Datos!$A$1:$H$256,5,FALSE) -> #N/A | D7: 61247156 | E7: =VLOOKUP(D7,Datos!$A$1:$H$256,6,FALSE) -> #N/A | F7: =VLOOKUP(D7,Datos!$A$1:$H$256,7,FALSE) -> #N/A | G7: =VLOOKUP(D7,Datos!$A$1:$H$256,8,FALSE) -> #N/A | H7: A | I7: INGENIERIA INDUSTRIAL | J7: SEDE CHINCHA | K7: ASISTIÓ | L7: 12 | M7: =IF(L7="","",(L7/25)) -> 0.48 | N7: 10 | O7: =IF(N7="","",(N7/10)) -> 1 | P7: 20 | Q7: =IF(P7="","",(P7/50)) -> 0.4 | R7: 5 | S7: =IF(R7="","",(R7/15)) -> 0.33333333 | T7: =L7+N7+P7+R7 -> 47 | U7: =IF(T7="","",(T7/100)) -> 0.47 | V7: =IF(U7=0,"NO INGRESÓ","INGRESÓ") -> INGRESÓ | W7: PRESENCIAL | X7: 45745 | Y7: MARZO | Z7: =VLOOKUP(D7,Datos!$A$1:$C$256,3,FALSE) -> #N/A
A8: 7 | B8: =VLOOKUP(D8,Datos!$A$1:$H$256,4,FALSE) -> #N/A | C8: =VLOOKUP(D8,Datos!$A$1:$H$256,5,FALSE) -> #N/A | D8: 61060130 | E8: =VLOOKUP(D8,Datos!$A$1:$H$256,6,FALSE) -> #N/A | F8: =VLOOKUP(D8,Datos!$A$1:$H$256,7,FALSE) -> #N/A | G8: =VLOOKUP(D8,Datos!$A$1:$H$256,8,FALSE) -> #N/A | H8: A | I8: INGENIERIA INDUSTRIAL | J8: SEDE CHINCHA | K8: ASISTIÓ | L8: 4 | M8: =IF(L8="","",(L8/25)) -> 0.16 | N8: 1 | O8: =IF(N8="","",(N8/10)) -> 0.1 | P8: 20 | Q8: =IF(P8="","",(P8/50)) -> 0.4 | R8: 4 | S8: =IF(R8="","",(R8/15)) -> 0.26666667 | T8: =L8+N8+P8+R8 -> 29 | U8: =IF(T8="","",(T8/100)) -> 0.29 | V8: =IF(U8=0,"NO INGRESÓ","INGRESÓ") -> INGRESÓ | W8: PRESENCIAL | X8: 45745 | Y8: MARZO | Z8: =VLOOKUP(D8,Datos!$A$1:$C$256,3,FALSE) -> #N/A
A9: 8 | B9: =VLOOKUP(D9,Datos!$A$1:$H$256,4,FALSE) -> #N/A | C9: =VLOOKUP(D9,Datos!$A$1:$H$256,5,FALSE) -> #N/A | D9: 72816481 | E9: =VLOOKUP(D9,Datos!$A$1:$H$256,6,FALSE) -> #N/A | F9: =VLOOKUP(D9,Datos!$A$1:$H$256,7,FALSE) -> #N/A | G9: =VLOOKUP(D9,Datos!$A$1:$H$256,8,FALSE) -> #N/A | H9: A | I9: INGENIERIA INDUSTRIAL | J9: SEDE CHINCHA | K9: ASISTIÓ | L9: 8 | M9: =IF(L9="","",(L9/25)) -> 0.32 | N9: 8 | O9: =IF(N9="","",(N9/10)) -> 0.8 | P9: 14 | Q9: =IF(P9="","",(P9/50)) -> 0.28 | R9: 7 | S9: =IF(R9="","",(R9/15)) -> 0.46666667 | T9: =L9+N9+P9+R9 -> 37 | U9: =IF(T9="","",(T9/100)) -> 0.37 | V9: =IF(U9=0,"NO INGRESÓ","INGRESÓ") -> INGRESÓ | W9: PRESENCIAL | X9: 45745 | Y9: MARZO | Z9: =VLOOKUP(D9,Datos!$A$1:$C$256,3,FALSE) -> #N/A
A10: 9 | B10: =VLOOKUP(D10,Datos!$A$1:$H$256,4,FALSE) -> #N/A | C10: =VLOOKUP(D10,Datos!$A$1:$H$256,5,FALSE) -> #N/A | D10: 60536595 | E10: =VLOOKUP(D10,Datos!$A$1:$H$256,6,FALSE) -> #N/A | F10: =VLOOKUP(D10,Datos!$A$1:$H$256,7,FALSE) -> #N/A | G10: =VLOOKUP(D10,Datos!$A$1:$H$256,8,FALSE) -> #N/A | H10: A | I10: INGENIERIA DE SISTEMAS | J10: SEDE CHINCHA | K10: ASISTIÓ | L10: 3 | M10: =IF(L10="","",(L10/25)) -> 0.12 | N10: 5 | O10: =IF(N10="","",(N10/10)) -> 0.5 | P10: 15 | Q10: =IF(P10="","",(P10/50)) -> 0.3 | R10: 6 | S10: =IF(R10="","",(R10/15)) -> 0.4 | T10: =L10+N10+P10+R10 -> 29 | U10: =IF(T10="","",(T10/100)) -> 0.29 | V10: =IF(U10=0,"NO INGRESÓ","INGRESÓ") -> INGRESÓ | W10: PRESENCIAL | X10: 45745 | Y10: MARZO | Z10: =VLOOKUP(D10,Datos!$A$1:$C$256,3,FALSE) -> #N/A
A11: 10 | B11: =VLOOKUP(D11,Datos!$A$1:$H$256,4,FALSE) -> #N/A | C11: =VLOOKUP(D11,Datos!$A$1:$H$256,5,FALSE) -> #N/A | D11: 60984495 | E11: =VLOOKUP(D11,Datos!$A$1:$H$256,6,FALSE) -> #N/A | F11: =VLOOKUP(D11,Datos!$A$1:$H$256,7,FALSE) -> #N/A | G11: =VLOOKUP(D11,Datos!$A$1:$H$256,8,FALSE) -> #N/A | H11: A | I11: INGENIERIA INDUSTRIAL | J11: SEDE CHINCHA | K11: ASISTIÓ | L11: 7 | M11: =IF(L11="","",(L11/25)) -> 0.28 | N11: 8 | O11: =IF(N11="","",(N11/10)) -> 0.8 | P11: 11 | Q11: =IF(P11="","",(P11/50)) -> 0.22 | R11: 4 | S11: =IF(R11="","",(R11/15)) -> 0.26666667 | T11: =L11+N11+P11+R11 -> 30 | U11: =IF(T11="","",(T11/100)) -> 0.3 | V11: =IF(U11=0,"NO INGRESÓ","INGRESÓ") -> INGRESÓ | W11: PRESENCIAL | X11: 45745 | Y11: MARZO | Z11: =VLOOKUP(D11,Datos!$A$1:$C$256,3,FALSE) -> #N/A
A12: 11 | B12: =VLOOKUP(D12,Datos!$A$1:$H$256,4,FALSE) -> #N/A | C12: =VLOOKUP(D12,Datos!$A$1:$H$256,5,FALSE) -> #N/A | D12: 74756208 | E12: =VLOOKUP(D12,Datos!$A$1:$H$256,6,FALSE) -> #N/A | F12: =VLOOKUP(D12,Datos!$A$1:$H$256,7,FALSE) -> #N/A | G12: =VLOOKUP(D12,Datos!$A$1:$H$256,8,FALSE) -> #N/A | H12: A | I12: INGENIERIA INDUSTRIAL | J12: SEDE CHINCHA | K12: ASISTIÓ | L12: 11 | M12: =IF(L12="","",(L12/25)) -> 0.44 | N12: 9 | O12: =IF(N12="","",(N12/10)) -> 0.9 | P12: 17 | Q12: =IF(P12="","",(P12/50)) -> 0.34 | R12: 4 | S12: =IF(R12="","",(R12/15)) -> 0.26666667 | T12: =L12+N12+P12+R12 -> 41 | U12: =IF(T12="","",(T12/100)) -> 0.41 | V12: =IF(U12=0,"NO INGRESÓ","INGRESÓ") -> INGRESÓ | W12: PRESENCIAL | X12: 45745 | Y12: MARZO | Z12: =VLOOKUP(D12,Datos!$A$1:$C$256,3,FALSE) -> #N/A
A13: 12 | B13: =VLOOKUP(D13,Datos!$A$1:$H$256,4,FALSE) -> #N/A | C13: =VLOOKUP(D13,Datos!$A$1:$H$256,5,FALSE) -> #N/A | D13: 60227545 | E13: =VLOOKUP(D13,Datos!$A$1:$H$256,6,FALSE) -> #N/A | F13: =VLOOKUP(D13,Datos!$A$1:$H$256,7,FALSE) -> #N/A | G13: =VLOOKUP(D13,Datos!$A$1:$H$256,8,FALSE) -> #N/A | H13: A | I13: ARQUITECTURA | J13: SEDE CHINCHA | K13: ASISTIÓ | L13: 13 | M13: =IF(L13="","",(L13/25)) -> 0.52 | N13: 2 | O13: =IF(N13="","",(N13/10)) -> 0.2 | P13: 12 | Q13: =IF(P13="","",(P13/50)) -> 0.24 | R13: 4 | S13: =IF(R13="","",(R13/15)) -> 0.26666667 | T13: =L13+N13+P13+R13 -> 31 | U13: =IF(T13="","",(T13/100)) -> 0.31 | V13: =IF(U13=0,"NO INGRESÓ","INGRESÓ") -> INGRESÓ | W13: PRESENCIAL | X13: 45745 | Y13: MARZO | Z13: =VLOOKUP(D13,Datos!$A$1:$C$256,3,FALSE) -> #N/A
... A69: 68 | B69: =VLOOKUP(D69,Datos!$A$1:$H$256,4,FALSE) -> #N/A | C69: =VLOOKUP(D69,Datos!$A$1:$H$256,5,FALSE) -> #N/A | D69: 60886936 | E69: =VLOOKUP(D69,Datos!$A$1:$H$256,6,FALSE) -> #N/A | F69: =VLOOKUP(D69,Datos!$A$1:$H$256,7,FALSE) -> #N/A | G69: =VLOOKUP(D69,Datos!$A$1:$H$256,8,FALSE) -> #N/A | H69: A | I69: INGENIERIA INDUSTRIAL | J69: SEDE CHINCHA | K69: ASISTIÓ | L69: 6 | M69: =IF(L69="","",(L69/25)) -> 0.24 | N69: 7 | O69: =IF(N69="","",(N69/10)) -> 0.7 | P69: 12 | Q69: =IF(P69="","",(P69/50)) -> 0.24 | R69: 3 | S69: =IF(R69="","",(R69/15)) -> 0.2 | T69: =L69+N69+P69+R69 -> 28 | U69: =IF(T69="","",(T69/100)) -> 0.28 | V69: =IF(U69=0,"NO INGRESÓ","INGRESÓ") -> INGRESÓ | W69: PRESENCIAL | X69: 45745 | Y69: MARZO | Z69: =VLOOKUP(D69,Datos!$A$1:$C$256,3,FALSE) -> #N/A
A70: 1 | B70: =VLOOKUP(D70,Datos!$A$1:$H$256,4,FALSE) -> #N/A | C70: =VLOOKUP(D70,Datos!$A$1:$H$256,5,FALSE) -> #N/A | D70: 47516374 | E70: =VLOOKUP(D70,Datos!$A$1:$H$256,6,FALSE) -> #N/A | F70: =VLOOKUP(D70,Datos!$A$1:$H$256,7,FALSE) -> #N/A | G70: =VLOOKUP(D70,Datos!$A$1:$H$256,8,FALSE) -> #N/A | H70: B | I70: TM OPTOMETRIA | J70: SEDE CHINCHA | K70: ASISTIÓ | L70: 16 | M70: =IF(L70="","",(L70/25)) -> 0.64 | N70: 8 | O70: =IF(N70="","",(N70/10)) -> 0.8 | P70: 11 | Q70: =IF(P70="","",(P70/35)) -> 0.31428571 | R70: 9 | S70: =IF(R70="","",(R70/30)) -> 0.3 | T70: =SUM(L70,N70,P70,R70) -> 44 | U70: =IF(T70="","",(T70/100)) -> 0.44 | V70: =IF(U70=0,"NO INGRESÓ","INGRESÓ") -> INGRESÓ | W70: PRESENCIAL | X70: 45745 | Y70: MARZO | Z70: =VLOOKUP(D70,Datos!$A$1:$C$256,3,FALSE) -> #N/A
A71: 2 | B71: =VLOOKUP(D71,Datos!$A$1:$H$256,4,FALSE) -> #N/A | C71: =VLOOKUP(D71,Datos!$A$1:$H$256,5,FALSE) -> #N/A | D71: 61247507 | E71: =VLOOKUP(D71,Datos!$A$1:$H$256,6,FALSE) -> #N/A | F71: =VLOOKUP(D71,Datos!$A$1:$H$256,7,FALSE) -> #N/A | G71: =VLOOKUP(D71,Datos!$A$1:$H$256,8,FALSE) -> #N/A | H71: B | I71: PSICOLOGIA | J71: SEDE CHINCHA | K71: ASISTIÓ | L71: 7 | M71: =IF(L71="","",(L71/25)) -> 0.28 | N71: 9 | O71: =IF(N71="","",(N71/10)) -> 0.9 | P71: 12 | Q71: =IF(P71="","",(P71/35)) -> 0.34285714 | R71: 6 | S71: =IF(R71="","",(R71/30)) -> 0.2 | T71: =SUM(L71,N71,P71,R71) -> 34 | U71: =IF(T71="","",(T71/100)) -> 0.34 | V71: =IF(U71=0,"NO INGRESÓ","INGRESÓ") -> INGRESÓ | W71: PRESENCIAL | X71: 45745 | Y71: MARZO | Z71: =VLOOKUP(D71,Datos!$A$1:$C$256,3,FALSE) -> #N/A
A72: 3 | B72: =VLOOKUP(D72,Datos!$A$1:$H$256,4,FALSE) -> #N/A | C72: =VLOOKUP(D72,Datos!$A$1:$H$256,5,FALSE) -> #N/A | D72: 40610052 | E72: =VLOOKUP(D72,Datos!$A$1:$H$256,6,FALSE) -> #N/A | F72: =VLOOKUP(D72,Datos!$A$1:$H$256,7,FALSE) -> #N/A | G72: =VLOOKUP(D72,Datos!$A$1:$H$256,8,FALSE) -> #N/A | H72: B | I72: TM OPTOMETRIA | J72: SEDE CHINCHA | K72: ASISTIÓ | L72: 11 | M72: =IF(L72="","",(L72/25)) -> 0.44 | N72: 9 | O72: =IF(N72="","",(N72/10)) -> 0.9 | P72: 12 | Q72: =IF(P72="","",(P72/35)) -> 0.34285714 | R72: 14 | S72: =IF(R72="","",(R72/30)) -> 0.46666667 | T72: =SUM(L72,N72,P72,R72) -> 46 | U72: =IF(T72="","",(T72/100)) -> 0.46 | V72: =IF(U72=0,"NO INGRESÓ","INGRESÓ") -> INGRESÓ | W72: PRESENCIAL | X72: 45745 | Y72: MARZO | Z72: =VLOOKUP(D72,Datos!$A$1:$C$256,3,FALSE) -> #N/A
A73: 4 | B73: =VLOOKUP(D73,Datos!$A$1:$H$256,4,FALSE) -> #N/A | C73: =VLOOKUP(D73,Datos!$A$1:$H$256,5,FALSE) -> #N/A | D73: 77018151 | E73: =VLOOKUP(D73,Datos!$A$1:$H$256,6,FALSE) -> #N/A | F73: =VLOOKUP(D73,Datos!$A$1:$H$256,7,FALSE) -> #N/A | G73: =VLOOKUP(D73,Datos!$A$1:$H$256,8,FALSE) -> #N/A | H73: B | I73: ENFERMERIA | J73: SEDE CHINCHA | K73: ASISTIÓ | L73: 9 | M73: =IF(L73="","",(L73/25)) -> 0.36 | N73: 7 | O73: =IF(N73="","",(N73/10)) -> 0.7 | P73: 9 | Q73: =IF(P73="","",(P73/35)) -> 0.25714286 | R73: 5 | S73: =IF(R73="","",(R73/30)) -> 0.16666667 | T73: =SUM(L73,N73,P73,R73) -> 30 | U73: =IF(T73="","",(T73/100)) -> 0.3 | V73: =IF(U73=0,"NO INGRESÓ","INGRESÓ") -> INGRESÓ | W73: PRESENCIAL | X73: 45745 | Y73: MARZO | Z73: =VLOOKUP(D73,Datos!$A$1:$C$256,3,FALSE) -> #N/A
A74: 5 | B74: =VLOOKUP(D74,Datos!$A$1:$H$256,4,FALSE) -> #N/A | C74: =VLOOKUP(D74,Datos!$A$1:$H$256,5,FALSE) -> #N/A | D74: 61298402 | E74: =VLOOKUP(D74,Datos!$A$1:$H$256,6,FALSE) -> #N/A | F74: =VLOOKUP(D74,Datos!$A$1:$H$256,7,FALSE) -> #N/A | G74: =VLOOKUP(D74,Datos!$A$1:$H$256,8,FALSE) -> #N/A | H74: B | I74: ENFERMERIA | J74: SEDE CHINCHA | K74: ASISTIÓ | L74: 4 | M74: =IF(L74="","",(L74/25)) -> 0.16 | N74: 9 | O74: =IF(N74="","",(N74/10)) -> 0.9 | P74: 5 | Q74: =IF(P74="","",(P74/35)) -> 0.14285714 | R74: 7 | S74: =IF(R74="","",(R74/30)) -> 0.23333333 | T74: =SUM(L74,N74,P74,R74) -> 25 | U74: =IF(T74="","",(T74/100)) -> 0.25 | V74: =IF(U74=0,"NO INGRESÓ","INGRESÓ") -> INGRESÓ | W74: PRESENCIAL | X74: 45745 | Y74: MARZO | Z74: =VLOOKUP(D74,Datos!$A$1:$C$256,3,FALSE) -> #N/A
A75: 6 | B75: =VLOOKUP(D75,Datos!$A$1:$H$256,4,FALSE) -> #N/A | C75: =VLOOKUP(D75,Datos!$A$1:$H$256,5,FALSE) -> #N/A | D75: 45918946 | E75: =VLOOKUP(D75,Datos!$A$1:$H$256,6,FALSE) -> #N/A | F75: =VLOOKUP(D75,Datos!$A$1:$H$256,7,FALSE) -> #N/A | G75: =VLOOKUP(D75,Datos!$A$1:$H$256,8,FALSE) -> #N/A | H75: B | I75: ENFERMERIA | J75: SEDE CHINCHA | K75: ASISTIÓ | L75: 11 | M75: =IF(L75="","",(L75/25)) -> 0.44 | N75: 6 | O75: =IF(N75="","",(N75/10)) -> 0.6 | P75: 15 | Q75: =IF(P75="","",(P75/35)) -> 0.42857143 | R75: 9 | S75: =IF(R75="","",(R75/30)) -> 0.3 | T75: =SUM(L75,N75,P75,R75) -> 41 | U75: =IF(T75="","",(T75/100)) -> 0.41 | V75: =IF(U75=0,"NO INGRESÓ","INGRESÓ") -> INGRESÓ | W75: PRESENCIAL | X75: 45745 | Y75: MARZO | Z75: =VLOOKUP(D75,Datos!$A$1:$C$256,3,FALSE) -> #N/A
A76: 7 | B76: =VLOOKUP(D76,Datos!$A$1:$H$256,4,FALSE) -> #N/A | C76: =VLOOKUP(D76,Datos!$A$1:$H$256,5,FALSE) -> #N/A | D76: 61145374 | E76: =VLOOKUP(D76,Datos!$A$1:$H$256,6,FALSE) -> #N/A | F76: =VLOOKUP(D76,Datos!$A$1:$H$256,7,FALSE) -> #N/A | G76: =VLOOKUP(D76,Datos!$A$1:$H$256,8,FALSE) -> #N/A | H76: B | I76: OBSTETRICIA | J76: SEDE CHINCHA | K76: ASISTIÓ | L76: 12 | M76: =IF(L76="","",(L76/25)) -> 0.48 | N76: 9 | O76: =IF(N76="","",(N76/10)) -> 0.9 | P76: 8 | Q76: =IF(P76="","",(P76/35)) -> 0.22857143 | R76: 10 | S76: =IF(R76="","",(R76/30)) -> 0.33333333 | T76: =SUM(L76,N76,P76,R76) -> 39 | U76: =IF(T76="","",(T76/100)) -> 0.39 | V76: =IF(U76=0,"NO INGRESÓ","INGRESÓ") -> INGRESÓ | W76: PRESENCIAL | X76: 45745 | Y76: MARZO | Z76: =VLOOKUP(D76,Datos!$A$1:$C$256,3,FALSE) -> #N/A
A77: 8 | B77: =VLOOKUP(D77,Datos!$A$1:$H$256,4,FALSE) -> #N/A | C77: =VLOOKUP(D77,Datos!$A$1:$H$256,5,FALSE) -> #N/A | D77: 60805765 | E77: =VLOOKUP(D77,Datos!$A$1:$H$256,6,FALSE) -> #N/A | F77: =VLOOKUP(D77,Datos!$A$1:$H$256,7,FALSE) -> #N/A | G77: =VLOOKUP(D77,Datos!$A$1:$H$256,8,FALSE) -> #N/A | H77: B | I77: TM OPTOMETRIA | J77: SEDE CHINCHA | K77: ASISTIÓ | L77: 10 | M77: =IF(L77="","",(L77/25)) -> 0.4 | N77: 6 | O77: =IF(N77="","",(N77/10)) -> 0.6 | P77: 16 | Q77: =IF(P77="","",(P77/35)) -> 0.45714286 | R77: 8 | S77: =IF(R77="","",(R77/30)) -> 0.26666667 | T77: =SUM(L77,N77,P77,R77) -> 40 | U77: =IF(T77="","",(T77/100)) -> 0.4 | V77: =IF(U77=0,"NO INGRESÓ","INGRESÓ") -> INGRESÓ | W77: PRESENCIAL | X77: 45745 | Y77: MARZO | Z77: =VLOOKUP(D77,Datos!$A$1:$C$256,3,FALSE) -> #N/A
A78: 9 | B78: =VLOOKUP(D78,Datos!$A$1:$H$256,4,FALSE) -> #N/A | C78: =VLOOKUP(D78,Datos!$A$1:$H$256,5,FALSE) -> #N/A | D78: 10764275 | E78: =VLOOKUP(D78,Datos!$A$1:$H$256,6,FALSE) -> #N/A | F78: =VLOOKUP(D78,Datos!$A$1:$H$256,7,FALSE) -> #N/A | G78: =VLOOKUP(D78,Datos!$A$1:$H$256,8,FALSE) -> #N/A | H78: B | I78: TM OPTOMETRIA | J78: SEDE CHINCHA | K78: ASISTIÓ | L78: 7 | M78: =IF(L78="","",(L78/25)) -> 0.28 | N78: 5 | O78: =IF(N78="","",(N78/10)) -> 0.5 | P78: 9 | Q78: =IF(P78="","",(P78/35)) -> 0.25714286 | R78: 5 | S78: =IF(R78="","",(R78/30)) -> 0.16666667 | T78: =SUM(L78,N78,P78,R78) -> 26 | U78: =IF(T78="","",(T78/100)) -> 0.26 | V78: =IF(U78=0,"NO INGRESÓ","INGRESÓ") -> INGRESÓ | W78: PRESENCIAL | X78: 45745 | Y78: MARZO | Z78: =VLOOKUP(D78,Datos!$A$1:$C$256,3,FALSE) -> #N/A
A79: 10 | B79: =VLOOKUP(D79,Datos!$A$1:$H$256,4,FALSE) -> #N/A | C79: =VLOOKUP(D79,Datos!$A$1:$H$256,5,FALSE) -> #N/A | D79: 8160587 | E79: =VLOOKUP(D79,Datos!$A$1:$H$256,6,FALSE) -> #N/A | F79: =VLOOKUP(D79,Datos!$A$1:$H$256,7,FALSE) -> #N/A | G79: =VLOOKUP(D79,Datos!$A$1:$H$256,8,FALSE) -> #N/A | H79: B | I79: TM OPTOMETRIA | J79: SEDE CHINCHA | K79: ASISTIÓ | L79: 8 | M79: =IF(L79="","",(L79/25)) -> 0.32 | N79: 4 | O79: =IF(N79="","",(N79/10)) -> 0.4 | P79: 9 | Q79: =IF(P79="","",(P79/35)) -> 0.25714286 | R79: 7 | S79: =IF(R79="","",(R79/30)) -> 0.23333333 | T79: =SUM(L79,N79,P79,R79) -> 28 | U79: =IF(T79="","",(T79/100)) -> 0.28 | V79: =IF(U79=0,"NO INGRESÓ","INGRESÓ") -> INGRESÓ | W79: PRESENCIAL | X79: 45745 | Y79: MARZO | Z79: =VLOOKUP(D79,Datos!$A$1:$C$256,3,FALSE) -> #N/A
A80: 11 | B80: =VLOOKUP(D80,Datos!$A$1:$H$256,4,FALSE) -> #N/A | C80: =VLOOKUP(D80,Datos!$A$1:$H$256,5,FALSE) -> #N/A | D80: 71453964 | E80: =VLOOKUP(D80,Datos!$A$1:$H$256,6,FALSE) -> #N/A | F80: =VLOOKUP(D80,Datos!$A$1:$H$256,7,FALSE) -> #N/A | G80: =VLOOKUP(D80,Datos!$A$1:$H$256,8,FALSE) -> #N/A | H80: B | I80: ENFERMERIA | J80: SEDE CHINCHA | K80: ASISTIÓ | L80: 16 | M80: =IF(L80="","",(L80/25)) -> 0.64 | N80: 10 | O80: =IF(N80="","",(N80/10)) -> 1 | P80: 18 | Q80: =IF(P80="","",(P80/35)) -> 0.51428571 | R80: 14 | S80: =IF(R80="","",(R80/30)) -> 0.46666667 | T80: =SUM(L80,N80,P80,R80) -> 58 | U80: =IF(T80="","",(T80/100)) -> 0.58 | V80: =IF(U80=0,"NO INGRESÓ","INGRESÓ") -> INGRESÓ | W80: PRESENCIAL | X80: 45745 | Y80: MARZO | Z80: =VLOOKUP(D80,Datos!$A$1:$C$256,3,FALSE) -> #N/A
A81: 12 | B81: =VLOOKUP(D81,Datos!$A$1:$H$256,4,FALSE) -> #N/A | C81: =VLOOKUP(D81,Datos!$A$1:$H$256,5,FALSE) -> #N/A | D81: 45562319 | E81: =VLOOKUP(D81,Datos!$A$1:$H$256,6,FALSE) -> #N/A | F81: =VLOOKUP(D81,Datos!$A$1:$H$256,7,FALSE) -> #N/A | G81: =VLOOKUP(D81,Datos!$A$1:$H$256,8,FALSE) -> #N/A | H81: B | I81: ENFERMERIA | J81: SEDE CHINCHA | K81: ASISTIÓ | L81: 13 | M81: =IF(L81="","",(L81/25)) -> 0.52 | N81: 7 | O81: =IF(N81="","",(N81/10)) -> 0.7 | P81: 20 | Q81: =IF(P81="","",(P81/35)) -> 0.57142857 | R81: 14 | S81: =IF(R81="","",(R81/30)) -> 0.46666667 | T81: =SUM(L81,N81,P81,R81) -> 54 | U81: =IF(T81="","",(T81/100)) -> 0.54 | V81: =IF(U81=0,"NO INGRESÓ","INGRESÓ") -> INGRESÓ | W81: PRESENCIAL | X81: 45745 | Y81: MARZO | Z81: =VLOOKUP(D81,Datos!$A$1:$C$256,3,FALSE) -> #N/A
... A253: 184 | B253: =VLOOKUP(D253,Datos!$A$1:$H$256,4,FALSE) -> #N/A | C253: =VLOOKUP(D253,Datos!$A$1:$H$256,5,FALSE) -> #N/A | D253: 40724398 | E253: =VLOOKUP(D253,Datos!$A$1:$H$256,6,FALSE) -> #N/A | F253: =VLOOKUP(D253,Datos!$A$1:$H$256,7,FALSE) -> #N/A | G253: =VLOOKUP(D253,Datos!$A$1:$H$256,8,FALSE) -> #N/A | H253: B | I253: TM OPTOMETRIA | J253: SEDE CHINCHA | K253: ASISTIÓ | L253: 14 | M253: =IF(L253="","",(L253/25)) -> 0.56 | N253: 10 | O253: =IF(N253="","",(N253/10)) -> 1 | P253: 20 | Q253: =IF(P253="","",(P253/35)) -> 0.57142857 | R253: 19 | S253: =IF(R253="","",(R253/30)) -> 0.63333333 | T253: =SUM(L253,N253,P253,R253) -> 63 | U253: =IF(T253="","",(T253/100)) -> 0.63 | V253: =IF(U253=0,"NO INGRESÓ","INGRESÓ") -> INGRESÓ | W253: PRESENCIAL | X253: 45745 | Y253: MARZO | Z253: =VLOOKUP(D253,Datos!$A$1:$C$256,3,FALSE) -> #N/A
A254: 1 | B254: =VLOOKUP(D254,Datos!$A$1:$H$256,4,FALSE) -> #N/A | C254: =VLOOKUP(D254,Datos!$A$1:$H$256,5,FALSE) -> #N/A | D254: 77661826 | E254: =VLOOKUP(D254,Datos!$A$1:$H$256,6,FALSE) -> #N/A | F254: =VLOOKUP(D254,Datos!$A$1:$H$256,7,FALSE) -> #N/A | G254: =VLOOKUP(D254,Datos!$A$1:$H$256,8,FALSE) -> #N/A | H254: C | I254: DERECHO | J254: SEDE CHINCHA | K254: ASISTIÓ | L254: 8 | M254: =IF(L254="","",(L254/25)) -> 0.32 | N254: 3 | O254: =IF(N254="","",(N254/10)) -> 0.3 | P254: 13 | Q254: =IF(P254="","",(P254/35)) -> 0.37142857 | R254: 9 | S254: =IF(R254="","",(R254/30)) -> 0.3 | T254: =L254+N254+P254+R254 -> 33 | U254: =IF(T254="","",(T254/100)) -> 0.33 | V254: =IF(U254=0,"NO INGRESÓ","INGRESÓ") -> INGRESÓ | W254: PRESENCIAL | X254: 45745 | Y254: MARZO | Z254: =VLOOKUP(D254,Datos!$A$1:$C$256,3,FALSE) -> #N/A
A255: 2 | B255: =VLOOKUP(D255,Datos!$A$1:$H$256,4,FALSE) -> #N/A | C255: =VLOOKUP(D255,Datos!$A$1:$H$256,5,FALSE) -> #N/A | D255: 60886720 | E255: =VLOOKUP(D255,Datos!$A$1:$H$256,6,FALSE) -> #N/A | F255: =VLOOKUP(D255,Datos!$A$1:$H$256,7,FALSE) -> #N/A | G255: =VLOOKUP(D255,Datos!$A$1:$H$256,8,FALSE) -> #N/A | H255: C | I255: ADMINISTRACION DE EMPRESAS | J255: SEDE CHINCHA | K255: ASISTIÓ | L255: 6 | M255: =IF(L255="","",(L255/25)) -> 0.24 | N255: 0 | O255: =IF(N255="","",(N255/10)) -> 0 | P255: 13 | Q255: =IF(P255="","",(P255/35)) -> 0.37142857 | R255: 11 | S255: =IF(R255="","",(R255/30)) -> 0.36666667 | T255: =L255+N255+P255+R255 -> 30 | U255: =IF(T255="","",(T255/100)) -> 0.3 | V255: =IF(U255=0,"NO INGRESÓ","INGRESÓ") -> INGRESÓ | W255: PRESENCIAL | X255: 45745 | Y255: MARZO | Z255: =VLOOKUP(D255,Datos!$A$1:$C$256,3,FALSE) -> #N/A
A256: 3 | B256: =VLOOKUP(D256,Datos!$A$1:$H$256,4,FALSE) -> #N/A | C256: =VLOOKUP(D256,Datos!$A$1:$H$256,5,FALSE) -> #N/A | D256: 61060628 | E256: =VLOOKUP(D256,Datos!$A$1:$H$256,6,FALSE) -> #N/A | F256: =VLOOKUP(D256,Datos!$A$1:$H$256,7,FALSE) -> #N/A | G256: =VLOOKUP(D256,Datos!$A$1:$H$256,8,FALSE) -> #N/A | H256: C | I256: ADMINISTRACION DE EMPRESAS | J256: SEDE CHINCHA | K256: ASISTIÓ | L256: 6 | M256: =IF(L256="","",(L256/25)) -> 0.24 | N256: 3 | O256: =IF(N256="","",(N256/10)) -> 0.3 | P256: 17 | Q256: =IF(P256="","",(P256/35)) -> 0.48571429 | R256: 6 | S256: =IF(R256="","",(R256/30)) -> 0.2 | T256: =L256+N256+P256+R256 -> 32 | U256: =IF(T256="","",(T256/100)) -> 0.32 | V256: =IF(U256=0,"NO INGRESÓ","INGRESÓ") -> INGRESÓ | W256: PRESENCIAL | X256: 45745 | Y256: MARZO | Z256: =VLOOKUP(D256,Datos!$A$1:$C$256,3,FALSE) -> #N/A
A257: 4 | B257: =VLOOKUP(D257,Datos!$A$1:$H$256,4,FALSE) -> #N/A | C257: =VLOOKUP(D257,Datos!$A$1:$H$256,5,FALSE) -> #N/A | D257: 60404599 | E257: =VLOOKUP(D257,Datos!$A$1:$H$256,6,FALSE) -> #N/A | F257: =VLOOKUP(D257,Datos!$A$1:$H$256,7,FALSE) -> #N/A | G257: =VLOOKUP(D257,Datos!$A$1:$H$256,8,FALSE) -> #N/A | H257: C | I257: DERECHO | J257: SEDE CHINCHA | K257: ASISTIÓ | L257: 8 | M257: =IF(L257="","",(L257/25)) -> 0.32 | N257: 3 | O257: =IF(N257="","",(N257/10)) -> 0.3 | P257: 12 | Q257: =IF(P257="","",(P257/35)) -> 0.34285714 | R257: 8 | S257: =IF(R257="","",(R257/30)) -> 0.26666667 | T257: =L257+N257+P257+R257 -> 31 | U257: =IF(T257="","",(T257/100)) -> 0.31 | V257: =IF(U257=0,"NO INGRESÓ","INGRESÓ") -> INGRESÓ | W257: PRESENCIAL | X257: 45745 | Y257: MARZO | Z257: =VLOOKUP(D257,Datos!$A$1:$C$256,3,FALSE) -> #N/A
A258: 5 | B258: =VLOOKUP(D258,Datos!$A$1:$H$256,4,FALSE) -> #N/A | C258: =VLOOKUP(D258,Datos!$A$1:$H$256,5,FALSE) -> #N/A | D258: 61205814 | E258: =VLOOKUP(D258,Datos!$A$1:$H$256,6,FALSE) -> #N/A | F258: =VLOOKUP(D258,Datos!$A$1:$H$256,7,FALSE) -> #N/A | G258: =VLOOKUP(D258,Datos!$A$1:$H$256,8,FALSE) -> #N/A | H258: C | I258: ADMINISTRACION DE EMPRESAS | J258: SEDE CHINCHA | K258: ASISTIÓ | L258: 7 | M258: =IF(L258="","",(L258/25)) -> 0.28 | N258: 3 | O258: =IF(N258="","",(N258/10)) -> 0.3 | P258: 20 | Q258: =IF(P258="","",(P258/35)) -> 0.57142857 | R258: 8 | S258: =IF(R258="","",(R258/30)) -> 0.26666667 | T258: =L258+N258+P258+R258 -> 38 | U258: =IF(T258="","",(T258/100)) -> 0.38 | V258: =IF(U258=0,"NO INGRESÓ","INGRESÓ") -> INGRESÓ | W258: PRESENCIAL | X258: 45745 | Y258: MARZO | Z258: =VLOOKUP(D258,Datos!$A$1:$C$256,3,FALSE) -> #N/A
